You are using fMRIPrep-20.2.6, and a newer version of fMRIPrep is available: 23.1.4.
Please check out our documentation about how and when to upgrade:
https://fmriprep.readthedocs.io/en/latest/faq.html#upgrading
exception calling callback for <Future at 0x7f4cce67de10 state=finished raised FileNotFoundError>
concurrent.futures.process._RemoteTraceback: 
"""
OSError: [Errno 28] No space left on device

During handling of the above exception, another exception occurred:

Traceback (most recent call last):
  File "/usr/local/miniconda/lib/python3.7/site-packages/nipype/pipeline/plugins/multiproc.py", line 67, in run_node
    result["result"] = node.run(updatehash=updatehash)
  File "/usr/local/miniconda/lib/python3.7/site-packages/nipype/pipeline/engine/nodes.py", line 521, in run
    result = self._run_interface(execute=True)
  File "/usr/local/miniconda/lib/python3.7/site-packages/nipype/pipeline/engine/nodes.py", line 639, in _run_interface
    return self._run_command(execute)
  File "/usr/local/miniconda/lib/python3.7/site-packages/nipype/pipeline/engine/nodes.py", line 722, in _run_command
    Path.write_text(outdir / "command.txt", f"{result.runtime.cmdline}\n")
  File "/usr/local/miniconda/lib/python3.7/pathlib.py", line 1209, in write_text
    return f.write(data)
OSError: [Errno 28] No space left on device

During handling of the above exception, another exception occurred:

Traceback (most recent call last):
  File "/usr/local/miniconda/lib/python3.7/concurrent/futures/process.py", line 232, in _process_worker
    r = call_item.fn(*call_item.args, **call_item.kwargs)
  File "/usr/local/miniconda/lib/python3.7/site-packages/nipype/pipeline/plugins/multiproc.py", line 70, in run_node
    result["result"] = node.result
  File "/usr/local/miniconda/lib/python3.7/site-packages/nipype/pipeline/engine/nodes.py", line 221, in result
    op.join(self.output_dir(), "result_%s.pklz" % self.name)
  File "/usr/local/miniconda/lib/python3.7/site-packages/nipype/pipeline/engine/utils.py", line 291, in load_resultfile
    raise FileNotFoundError(results_file)
FileNotFoundError: /scratch/fmriprep/fmriprep_wf/single_subject_tcb2073_wf/func_preproc_ses_01_task_TSSblock_run_07_wf/ica_aroma_wf/ica_aroma/result_ica_aroma.pklz
"""

The above exception was the direct cause of the following exception:

Traceback (most recent call last):
  File "/usr/local/miniconda/lib/python3.7/concurrent/futures/_base.py", line 324, in _invoke_callbacks
    callback(self)
  File "/usr/local/miniconda/lib/python3.7/site-packages/nipype/pipeline/plugins/multiproc.py", line 159, in _async_callback
    result = args.result()
  File "/usr/local/miniconda/lib/python3.7/concurrent/futures/_base.py", line 425, in result
    return self.__get_result()
  File "/usr/local/miniconda/lib/python3.7/concurrent/futures/_base.py", line 384, in __get_result
    raise self._exception
FileNotFoundError: /scratch/fmriprep/fmriprep_wf/single_subject_tcb2073_wf/func_preproc_ses_01_task_TSSblock_run_07_wf/ica_aroma_wf/ica_aroma/result_ica_aroma.pklz
exception calling callback for <Future at 0x7f4ccf41ce48 state=finished raised FileNotFoundError>
concurrent.futures.process._RemoteTraceback: 
"""
OSError: [Errno 28] No space left on device

During handling of the above exception, another exception occurred:

Traceback (most recent call last):
  File "/usr/local/miniconda/lib/python3.7/site-packages/nipype/pipeline/plugins/multiproc.py", line 67, in run_node
    result["result"] = node.run(updatehash=updatehash)
  File "/usr/local/miniconda/lib/python3.7/site-packages/nipype/pipeline/engine/nodes.py", line 521, in run
    result = self._run_interface(execute=True)
  File "/usr/local/miniconda/lib/python3.7/site-packages/nipype/pipeline/engine/nodes.py", line 639, in _run_interface
    return self._run_command(execute)
  File "/usr/local/miniconda/lib/python3.7/site-packages/nipype/pipeline/engine/nodes.py", line 722, in _run_command
    Path.write_text(outdir / "command.txt", f"{result.runtime.cmdline}\n")
  File "/usr/local/miniconda/lib/python3.7/pathlib.py", line 1209, in write_text
    return f.write(data)
OSError: [Errno 28] No space left on device

During handling of the above exception, another exception occurred:

Traceback (most recent call last):
  File "/usr/local/miniconda/lib/python3.7/concurrent/futures/process.py", line 232, in _process_worker
    r = call_item.fn(*call_item.args, **call_item.kwargs)
  File "/usr/local/miniconda/lib/python3.7/site-packages/nipype/pipeline/plugins/multiproc.py", line 70, in run_node
    result["result"] = node.result
  File "/usr/local/miniconda/lib/python3.7/site-packages/nipype/pipeline/engine/nodes.py", line 221, in result
    op.join(self.output_dir(), "result_%s.pklz" % self.name)
  File "/usr/local/miniconda/lib/python3.7/site-packages/nipype/pipeline/engine/utils.py", line 291, in load_resultfile
    raise FileNotFoundError(results_file)
FileNotFoundError: /scratch/fmriprep/fmriprep_wf/single_subject_tcb2073_wf/func_preproc_ses_01_task_TSSblock_run_06_wf/ica_aroma_wf/melodic/result_melodic.pklz
"""

The above exception was the direct cause of the following exception:

Traceback (most recent call last):
  File "/usr/local/miniconda/lib/python3.7/concurrent/futures/_base.py", line 324, in _invoke_callbacks
    callback(self)
  File "/usr/local/miniconda/lib/python3.7/site-packages/nipype/pipeline/plugins/multiproc.py", line 159, in _async_callback
    result = args.result()
  File "/usr/local/miniconda/lib/python3.7/concurrent/futures/_base.py", line 425, in result
    return self.__get_result()
  File "/usr/local/miniconda/lib/python3.7/concurrent/futures/_base.py", line 384, in __get_result
    raise self._exception
FileNotFoundError: /scratch/fmriprep/fmriprep_wf/single_subject_tcb2073_wf/func_preproc_ses_01_task_TSSblock_run_06_wf/ica_aroma_wf/melodic/result_melodic.pklz
exception calling callback for <Future at 0x7f4cce3eff98 state=finished raised FileNotFoundError>
concurrent.futures.process._RemoteTraceback: 
"""
OSError: [Errno 28] No space left on device

During handling of the above exception, another exception occurred:

Traceback (most recent call last):
  File "/usr/local/miniconda/lib/python3.7/site-packages/nipype/pipeline/plugins/multiproc.py", line 67, in run_node
    result["result"] = node.run(updatehash=updatehash)
  File "/usr/local/miniconda/lib/python3.7/site-packages/nipype/pipeline/engine/nodes.py", line 521, in run
    result = self._run_interface(execute=True)
  File "/usr/local/miniconda/lib/python3.7/site-packages/nipype/pipeline/engine/nodes.py", line 639, in _run_interface
    return self._run_command(execute)
  File "/usr/local/miniconda/lib/python3.7/site-packages/nipype/pipeline/engine/nodes.py", line 722, in _run_command
    Path.write_text(outdir / "command.txt", f"{result.runtime.cmdline}\n")
  File "/usr/local/miniconda/lib/python3.7/pathlib.py", line 1209, in write_text
    return f.write(data)
OSError: [Errno 28] No space left on device

During handling of the above exception, another exception occurred:

Traceback (most recent call last):
  File "/usr/local/miniconda/lib/python3.7/concurrent/futures/process.py", line 232, in _process_worker
    r = call_item.fn(*call_item.args, **call_item.kwargs)
  File "/usr/local/miniconda/lib/python3.7/site-packages/nipype/pipeline/plugins/multiproc.py", line 70, in run_node
    result["result"] = node.result
  File "/usr/local/miniconda/lib/python3.7/site-packages/nipype/pipeline/engine/nodes.py", line 221, in result
    op.join(self.output_dir(), "result_%s.pklz" % self.name)
  File "/usr/local/miniconda/lib/python3.7/site-packages/nipype/pipeline/engine/utils.py", line 291, in load_resultfile
    raise FileNotFoundError(results_file)
FileNotFoundError: /scratch/fmriprep/fmriprep_wf/single_subject_tcb2073_wf/func_preproc_ses_01_task_TSSblock_run_04_wf/ica_aroma_wf/ica_aroma/result_ica_aroma.pklz
"""

The above exception was the direct cause of the following exception:

Traceback (most recent call last):
  File "/usr/local/miniconda/lib/python3.7/concurrent/futures/_base.py", line 324, in _invoke_callbacks
    callback(self)
  File "/usr/local/miniconda/lib/python3.7/site-packages/nipype/pipeline/plugins/multiproc.py", line 159, in _async_callback
    result = args.result()
  File "/usr/local/miniconda/lib/python3.7/concurrent/futures/_base.py", line 425, in result
    return self.__get_result()
  File "/usr/local/miniconda/lib/python3.7/concurrent/futures/_base.py", line 384, in __get_result
    raise self._exception
FileNotFoundError: /scratch/fmriprep/fmriprep_wf/single_subject_tcb2073_wf/func_preproc_ses_01_task_TSSblock_run_04_wf/ica_aroma_wf/ica_aroma/result_ica_aroma.pklz
exception calling callback for <Future at 0x7f4cd03536d8 state=finished raised FileNotFoundError>
concurrent.futures.process._RemoteTraceback: 
"""
OSError: [Errno 28] No space left on device

During handling of the above exception, another exception occurred:

Traceback (most recent call last):
  File "/usr/local/miniconda/lib/python3.7/site-packages/nipype/pipeline/plugins/multiproc.py", line 67, in run_node
    result["result"] = node.run(updatehash=updatehash)
  File "/usr/local/miniconda/lib/python3.7/site-packages/nipype/pipeline/engine/nodes.py", line 516, in run
    write_node_report(self, is_mapnode=isinstance(self, MapNode))
  File "/usr/local/miniconda/lib/python3.7/site-packages/nipype/pipeline/engine/utils.py", line 128, in write_node_report
    report_file.write_text("\n".join(lines))
  File "/usr/local/miniconda/lib/python3.7/pathlib.py", line 1209, in write_text
    return f.write(data)
OSError: [Errno 28] No space left on device

During handling of the above exception, another exception occurred:

Traceback (most recent call last):
  File "/usr/local/miniconda/lib/python3.7/concurrent/futures/process.py", line 232, in _process_worker
    r = call_item.fn(*call_item.args, **call_item.kwargs)
  File "/usr/local/miniconda/lib/python3.7/site-packages/nipype/pipeline/plugins/multiproc.py", line 70, in run_node
    result["result"] = node.result
  File "/usr/local/miniconda/lib/python3.7/site-packages/nipype/pipeline/engine/nodes.py", line 221, in result
    op.join(self.output_dir(), "result_%s.pklz" % self.name)
  File "/usr/local/miniconda/lib/python3.7/site-packages/nipype/pipeline/engine/utils.py", line 291, in load_resultfile
    raise FileNotFoundError(results_file)
FileNotFoundError: /scratch/fmriprep/fmriprep_wf/single_subject_tcb2073_wf/func_preproc_ses_01_task_TSSblock_run_08_wf/ica_aroma_wf/ica_aroma/result_ica_aroma.pklz
"""

The above exception was the direct cause of the following exception:

Traceback (most recent call last):
  File "/usr/local/miniconda/lib/python3.7/concurrent/futures/_base.py", line 324, in _invoke_callbacks
    callback(self)
  File "/usr/local/miniconda/lib/python3.7/site-packages/nipype/pipeline/plugins/multiproc.py", line 159, in _async_callback
    result = args.result()
  File "/usr/local/miniconda/lib/python3.7/concurrent/futures/_base.py", line 425, in result
    return self.__get_result()
  File "/usr/local/miniconda/lib/python3.7/concurrent/futures/_base.py", line 384, in __get_result
    raise self._exception
FileNotFoundError: /scratch/fmriprep/fmriprep_wf/single_subject_tcb2073_wf/func_preproc_ses_01_task_TSSblock_run_08_wf/ica_aroma_wf/ica_aroma/result_ica_aroma.pklz
exception calling callback for <Future at 0x7f4cce3b8eb8 state=finished raised FileNotFoundError>
concurrent.futures.process._RemoteTraceback: 
"""
OSError: [Errno 28] No space left on device

During handling of the above exception, another exception occurred:

Traceback (most recent call last):
  File "/usr/local/miniconda/lib/python3.7/site-packages/nipype/pipeline/plugins/multiproc.py", line 67, in run_node
    result["result"] = node.run(updatehash=updatehash)
  File "/usr/local/miniconda/lib/python3.7/site-packages/nipype/pipeline/engine/nodes.py", line 516, in run
    write_node_report(self, is_mapnode=isinstance(self, MapNode))
  File "/usr/local/miniconda/lib/python3.7/site-packages/nipype/pipeline/engine/utils.py", line 128, in write_node_report
    report_file.write_text("\n".join(lines))
  File "/usr/local/miniconda/lib/python3.7/pathlib.py", line 1209, in write_text
    return f.write(data)
OSError: [Errno 28] No space left on device

During handling of the above exception, another exception occurred:

Traceback (most recent call last):
  File "/usr/local/miniconda/lib/python3.7/concurrent/futures/process.py", line 232, in _process_worker
    r = call_item.fn(*call_item.args, **call_item.kwargs)
  File "/usr/local/miniconda/lib/python3.7/site-packages/nipype/pipeline/plugins/multiproc.py", line 70, in run_node
    result["result"] = node.result
  File "/usr/local/miniconda/lib/python3.7/site-packages/nipype/pipeline/engine/nodes.py", line 221, in result
    op.join(self.output_dir(), "result_%s.pklz" % self.name)
  File "/usr/local/miniconda/lib/python3.7/site-packages/nipype/pipeline/engine/utils.py", line 291, in load_resultfile
    raise FileNotFoundError(results_file)
FileNotFoundError: /scratch/fmriprep/fmriprep_wf/single_subject_tcb2073_wf/func_preproc_ses_01_task_TSSblock_run_02_wf/ica_aroma_wf/ica_aroma/result_ica_aroma.pklz
"""

The above exception was the direct cause of the following exception:

Traceback (most recent call last):
  File "/usr/local/miniconda/lib/python3.7/concurrent/futures/_base.py", line 324, in _invoke_callbacks
    callback(self)
  File "/usr/local/miniconda/lib/python3.7/site-packages/nipype/pipeline/plugins/multiproc.py", line 159, in _async_callback
    result = args.result()
  File "/usr/local/miniconda/lib/python3.7/concurrent/futures/_base.py", line 425, in result
    return self.__get_result()
  File "/usr/local/miniconda/lib/python3.7/concurrent/futures/_base.py", line 384, in __get_result
    raise self._exception
FileNotFoundError: /scratch/fmriprep/fmriprep_wf/single_subject_tcb2073_wf/func_preproc_ses_01_task_TSSblock_run_02_wf/ica_aroma_wf/ica_aroma/result_ica_aroma.pklz
exception calling callback for <Future at 0x7f4cce642eb8 state=finished raised FileNotFoundError>
concurrent.futures.process._RemoteTraceback: 
"""
OSError: [Errno 28] No space left on device

During handling of the above exception, another exception occurred:

Traceback (most recent call last):
  File "/usr/local/miniconda/lib/python3.7/site-packages/nipype/pipeline/plugins/multiproc.py", line 67, in run_node
    result["result"] = node.run(updatehash=updatehash)
  File "/usr/local/miniconda/lib/python3.7/site-packages/nipype/pipeline/engine/nodes.py", line 521, in run
    result = self._run_interface(execute=True)
  File "/usr/local/miniconda/lib/python3.7/site-packages/nipype/pipeline/engine/nodes.py", line 639, in _run_interface
    return self._run_command(execute)
  File "/usr/local/miniconda/lib/python3.7/site-packages/nipype/pipeline/engine/nodes.py", line 722, in _run_command
    Path.write_text(outdir / "command.txt", f"{result.runtime.cmdline}\n")
  File "/usr/local/miniconda/lib/python3.7/pathlib.py", line 1209, in write_text
    return f.write(data)
OSError: [Errno 28] No space left on device

During handling of the above exception, another exception occurred:

Traceback (most recent call last):
  File "/usr/local/miniconda/lib/python3.7/concurrent/futures/process.py", line 232, in _process_worker
    r = call_item.fn(*call_item.args, **call_item.kwargs)
  File "/usr/local/miniconda/lib/python3.7/site-packages/nipype/pipeline/plugins/multiproc.py", line 70, in run_node
    result["result"] = node.result
  File "/usr/local/miniconda/lib/python3.7/site-packages/nipype/pipeline/engine/nodes.py", line 221, in result
    op.join(self.output_dir(), "result_%s.pklz" % self.name)
  File "/usr/local/miniconda/lib/python3.7/site-packages/nipype/pipeline/engine/utils.py", line 291, in load_resultfile
    raise FileNotFoundError(results_file)
FileNotFoundError: /scratch/fmriprep/fmriprep_wf/single_subject_tcb2073_wf/func_preproc_ses_01_task_TSSblock_run_03_wf/ica_aroma_wf/melodic/result_melodic.pklz
"""

The above exception was the direct cause of the following exception:

Traceback (most recent call last):
  File "/usr/local/miniconda/lib/python3.7/concurrent/futures/_base.py", line 324, in _invoke_callbacks
    callback(self)
  File "/usr/local/miniconda/lib/python3.7/site-packages/nipype/pipeline/plugins/multiproc.py", line 159, in _async_callback
    result = args.result()
  File "/usr/local/miniconda/lib/python3.7/concurrent/futures/_base.py", line 425, in result
    return self.__get_result()
  File "/usr/local/miniconda/lib/python3.7/concurrent/futures/_base.py", line 384, in __get_result
    raise self._exception
FileNotFoundError: /scratch/fmriprep/fmriprep_wf/single_subject_tcb2073_wf/func_preproc_ses_01_task_TSSblock_run_03_wf/ica_aroma_wf/melodic/result_melodic.pklz
exception calling callback for <Future at 0x7f4ccf36fef0 state=finished raised FileNotFoundError>
concurrent.futures.process._RemoteTraceback: 
"""
OSError: [Errno 28] No space left on device

During handling of the above exception, another exception occurred:

Traceback (most recent call last):
  File "/usr/local/miniconda/lib/python3.7/site-packages/nipype/pipeline/plugins/multiproc.py", line 67, in run_node
    result["result"] = node.run(updatehash=updatehash)
  File "/usr/local/miniconda/lib/python3.7/site-packages/nipype/pipeline/engine/nodes.py", line 521, in run
    result = self._run_interface(execute=True)
  File "/usr/local/miniconda/lib/python3.7/site-packages/nipype/pipeline/engine/nodes.py", line 639, in _run_interface
    return self._run_command(execute)
  File "/usr/local/miniconda/lib/python3.7/site-packages/nipype/pipeline/engine/nodes.py", line 722, in _run_command
    Path.write_text(outdir / "command.txt", f"{result.runtime.cmdline}\n")
  File "/usr/local/miniconda/lib/python3.7/pathlib.py", line 1209, in write_text
    return f.write(data)
OSError: [Errno 28] No space left on device

During handling of the above exception, another exception occurred:

Traceback (most recent call last):
  File "/usr/local/miniconda/lib/python3.7/concurrent/futures/process.py", line 232, in _process_worker
    r = call_item.fn(*call_item.args, **call_item.kwargs)
  File "/usr/local/miniconda/lib/python3.7/site-packages/nipype/pipeline/plugins/multiproc.py", line 70, in run_node
    result["result"] = node.result
  File "/usr/local/miniconda/lib/python3.7/site-packages/nipype/pipeline/engine/nodes.py", line 221, in result
    op.join(self.output_dir(), "result_%s.pklz" % self.name)
  File "/usr/local/miniconda/lib/python3.7/site-packages/nipype/pipeline/engine/utils.py", line 291, in load_resultfile
    raise FileNotFoundError(results_file)
FileNotFoundError: /scratch/fmriprep/fmriprep_wf/single_subject_tcb2073_wf/func_preproc_ses_01_task_TSSblock_run_05_wf/ica_aroma_wf/melodic/result_melodic.pklz
"""

The above exception was the direct cause of the following exception:

Traceback (most recent call last):
  File "/usr/local/miniconda/lib/python3.7/concurrent/futures/_base.py", line 324, in _invoke_callbacks
    callback(self)
  File "/usr/local/miniconda/lib/python3.7/site-packages/nipype/pipeline/plugins/multiproc.py", line 159, in _async_callback
    result = args.result()
  File "/usr/local/miniconda/lib/python3.7/concurrent/futures/_base.py", line 425, in result
    return self.__get_result()
  File "/usr/local/miniconda/lib/python3.7/concurrent/futures/_base.py", line 384, in __get_result
    raise self._exception
FileNotFoundError: /scratch/fmriprep/fmriprep_wf/single_subject_tcb2073_wf/func_preproc_ses_01_task_TSSblock_run_05_wf/ica_aroma_wf/melodic/result_melodic.pklz
exception calling callback for <Future at 0x7f4cce3f88d0 state=finished raised FileNotFoundError>
concurrent.futures.process._RemoteTraceback: 
"""
OSError: [Errno 28] No space left on device

During handling of the above exception, another exception occurred:

Traceback (most recent call last):
  File "/usr/local/miniconda/lib/python3.7/site-packages/nipype/pipeline/plugins/multiproc.py", line 67, in run_node
    result["result"] = node.run(updatehash=updatehash)
  File "/usr/local/miniconda/lib/python3.7/site-packages/nipype/pipeline/engine/nodes.py", line 521, in run
    result = self._run_interface(execute=True)
  File "/usr/local/miniconda/lib/python3.7/site-packages/nipype/pipeline/engine/nodes.py", line 639, in _run_interface
    return self._run_command(execute)
  File "/usr/local/miniconda/lib/python3.7/site-packages/nipype/pipeline/engine/nodes.py", line 722, in _run_command
    Path.write_text(outdir / "command.txt", f"{result.runtime.cmdline}\n")
  File "/usr/local/miniconda/lib/python3.7/pathlib.py", line 1209, in write_text
    return f.write(data)
OSError: [Errno 28] No space left on device

During handling of the above exception, another exception occurred:

Traceback (most recent call last):
  File "/usr/local/miniconda/lib/python3.7/concurrent/futures/process.py", line 232, in _process_worker
    r = call_item.fn(*call_item.args, **call_item.kwargs)
  File "/usr/local/miniconda/lib/python3.7/site-packages/nipype/pipeline/plugins/multiproc.py", line 70, in run_node
    result["result"] = node.result
  File "/usr/local/miniconda/lib/python3.7/site-packages/nipype/pipeline/engine/nodes.py", line 221, in result
    op.join(self.output_dir(), "result_%s.pklz" % self.name)
  File "/usr/local/miniconda/lib/python3.7/site-packages/nipype/pipeline/engine/utils.py", line 291, in load_resultfile
    raise FileNotFoundError(results_file)
FileNotFoundError: /scratch/fmriprep/fmriprep_wf/single_subject_tcb2073_wf/func_preproc_ses_01_task_TSSblock_run_01_wf/ica_aroma_wf/ica_aroma/result_ica_aroma.pklz
"""

The above exception was the direct cause of the following exception:

Traceback (most recent call last):
  File "/usr/local/miniconda/lib/python3.7/concurrent/futures/_base.py", line 324, in _invoke_callbacks
    callback(self)
  File "/usr/local/miniconda/lib/python3.7/site-packages/nipype/pipeline/plugins/multiproc.py", line 159, in _async_callback
    result = args.result()
  File "/usr/local/miniconda/lib/python3.7/concurrent/futures/_base.py", line 425, in result
    return self.__get_result()
  File "/usr/local/miniconda/lib/python3.7/concurrent/futures/_base.py", line 384, in __get_result
    raise self._exception
FileNotFoundError: /scratch/fmriprep/fmriprep_wf/single_subject_tcb2073_wf/func_preproc_ses_01_task_TSSblock_run_01_wf/ica_aroma_wf/ica_aroma/result_ica_aroma.pklz
slurmstepd: error: *** JOB 12260173 ON node1649 CANCELLED AT 2023-12-06T02:17:27 DUE TO TIME LIMIT ***
